Workbook

Sheet Valuation
D1: 1 | E1: 2 | F1: 3 | G1: 4 | H1: 5
A2: Particulars | D2: Forecast
B3: Unit | D3: 2025 | E3: =D3+1 -> 2026 | F3: =E3+1 -> 2027 | G3: =F3+1 -> 2028 | H3: =G3+1 -> 2029
A4: EBIT | B4: $ | D4: ='P&L'!G26 -> 3867.2139 | E4: ='P&L'!H26 -> 4196.4249 | F4: ='P&L'!I26 -> 4570.0913 | G4: ='P&L'!J26 -> 4995.7707 | H4: ='P&L'!K26 -> 5484.5687
A5: Tax rate | D5: ='P&L'!G73 -> 0.23233941 | E5: =(D5+($H$5-$D$5)/4) -> 0.24175456 | F5: =(E5+($H$5-$D$5)/4) -> 0.2511697 | G5: =(F5+($H$5-$D$5)/4) -> 0.26058485 | H5: 0.27
A6: Less:Income taxes | D6: =D4*D5 -> 898.50618 | E6: =E4*E5 -> 1014.5049 | F6: =F4*F5 -> 1147.8685 | G6: =G4*G5 -> 1301.8222 | H6: =H4*H5 -> 1480.8336
A7: Net operating profit after tax(NOPAT) | D7: =D4-D6 -> 2968.7077 | E7: =E4-E6 -> 3181.9201 | F7: =F4-F6 -> 3422.2228 | G7: =G4-G6 -> 3693.9485 | H7: =H4-H6 -> 4003.7352
A8: Add:Depreciation & Amortization | D8: ='P&L'!G76 -> 608.19947 | E8: ='P&L'!H76 -> 622.28737 | F8: ='P&L'!I76 -> 640.44046 | G8: ='P&L'!J76 -> 662.96099 | H8: ='P&L'!K76 -> 690.49352
A9: Changes in Working capital | D9: =SUM(CFS!C11:C16) -> 187.95243 | E9: =SUM(CFS!D11:D16) -> 173.42594 | F9: =SUM(CFS!E11:E16) -> 197.71663 | G9: =SUM(CFS!F11:F16) -> 228.61677 | H9: =SUM(CFS!G11:G16) -> 266.29998
A10: Less:Capex | D10: =CFS!C20 -> -194.88683 | E10: =CFS!D20 -> -269.1853 | F10: =CFS!E20 -> -346.86105 | G10: =CFS!F20 -> -430.31191 | H10: =CFS!G20 -> -526.07918
A11: FCFF | D11: =SUM(D7:D10) -> 3569.9727 | E11: =SUM(E7:E10) -> 3708.4481 | F11: =SUM(F7:F10) -> 3913.5189 | G11: =SUM(G7:G10) -> 4155.2144 | H11: =SUM(H7:H10) -> 4434.4495
A14: Terminal Value | H14: =H11*(1+C18)/(C19-C18) -> 150992.38
A15: Total cash flow | D15: =D11+D14 -> 3569.9727 | E15: =E11+E14 -> 3708.4481 | F15: =F11+F14 -> 3913.5189 | G15: =G11+G14 -> 4155.2144 | H15: =H11+H14 -> 155426.83
A16: PV of Cash flows | D16: =D15/(1+$C$19)^D1 -> 3399.783 | E16: =E15/(1+$C$19)^E1 -> 3363.2937 | F16: =F15/(1+$C$19)^F1 -> 3380.0748 | G16: =G15/(1+$C$19)^G1 -> 3417.7368 | H16: =H15/(1+$C$19)^H1 -> 121746.77
A18: Growth Rate | C18: 0.0201
A19: WACC | C19: =('Cost of Capital'!B17*'Cost of Capital'!E21/'Cost of Capital'!H21)+('Cost of Debt'!B14*'Cost of Capital'!G21/'Cost of Capital'!H21) -> 0.050059008
I21: WACC
A22: Value of Firm | C22: =SUM(D16:H16) -> 135307.66 | G22: Growth | H22: =$C$28 -> 156.04308 | I22: =J22-0.5% -> 0.035059008 | J22: =K22-0.5% -> 0.040059008 | K22: =L22-0.5% -> 0.045059008 | L22: =C19 -> 0.050059008 | M22: =L22+0.5% -> 0.055059008 | N22: =M22+0.5% -> 0.060059008 | O22: =N22+0.5% -> 0.065059008
A23: Less: Value of Debt | C23: =SUM('Balance Sheet'!F18,'Balance Sheet'!F19,'Balance Sheet'!F24) -> 7949 | H23: =H24-0.2% -> 0.0141 | I23: 342.47 | J23: 250.87 | K23: 193.31 | L23: 155.95 | M23: 139.88 | N23: 123.41 | O23: 110.13
A24: Add:Cash & Cash Equivalents | C24: ='Balance Sheet'!F5 -> 1096 | H24: =H25-0.2% -> 0.0161 | I24: 336.06 | J24: 247.05 | K24: 190.11 | L24: 156 | M24: 138.12 | N24: 121.38 | O24: 107.36
A25: Add:Investments | C25: 0 | H25: =H26-0.2% -> 0.0181 | I25: 329.03 | J25: 243.17 | K25: 186.97 | L25: 156 | M25: 136.55 | N25: 119.64 | O25: 105.64
A26: Value of Equity | C26: =C22-C23+C24+C25 -> 128454.66 | H26: =C18 -> 0.0201 | I26: 322.39 | J26: 239.22 | K26: 183.91 | L26: 155.95 | M26: 134.7 | N26: 118.39 | O26: 104.09
A27: No.Of Shares Outstanding | C27: ='P&L'!F60 -> 823.2 | H27: =H26+0.2% -> 0.0221 | I27: 316.09 | J27: 235.26 | K27: 180.9 | L27: 155.97 | M27: 133.28 | N27: 116.94 | O27: 102.96
A28: Fair Value/Share | C28: =C26/C27 -> 156.04308 | H28: =H27+0.2% -> 0.0241 | I28: 310.1 | J28: 231.42 | K28: 177.98 | L28: 155.96 | M28: 131.7 | N28: 115.49 | O28: 102.05
H29: =H28+0.2% -> 0.0261 | I29: 304.41 | J29: 227.6 | K29: 175.12 | L29: 155.96 | M29: 130.04 | N29: 113.71 | O29: 100.97
E46: =L32-K32 -> 0
E47: =M32-L32 -> 0

Sheet Cost of Debt
A1: Cost of Debt
A2: Marginal Tax Rate | B2: 0.27
A4: Market Based Method
A5: Yield of colgate range
A6: FV(Face Value) | B6: 1000
A7: CMP | B7: 757.02
A8: Redemption | B8: 51086
A9: Valuation Date | B9: 45897
A10: Time to Maturity | B10: =YEARFRAC(B9,B8,1) -> 14.208653
A11: Coupon Rate | B11: 0.00875
A12: Coupon Amount | B12: =B11*B6 -> 8.75
A13: Cost of Debt(Pre-Tax) | B13: =RATE(B10,B12,-B7,B6,0) -> 0.030006062
A14: Cost of Debt(Post-Tax) | B14: =B13*(1-B2) -> 0.021904425
A16: Premium Based Method
A17: Risk free Rate | B17: ='Cost of Capital'!B5 -> 0.0407
A18: Risk Premium | B18: 0.006
A19: Cost of Debt(pre-Tax) | B19: =B17+B18 -> 0.0467
A20: Cost of Debt(Post-Tax) | B20: =B19*(1-B2) -> 0.034091

Sheet Cost of Capital
A1: Particulars
B2: Unit
A4: Cost of Equity
A5: Risk free rate of returns | B5: 0.0407
A6: Returns from Market(Historical) | B6: =B13 -> 0.07546018
A8: Date | B8: year | C8: Index Value
A9: 31048 | B9: 1985 | C9: 1097.2
A10: 45907 | B10: 2025 | C10: 21165.05
A12: Total Time | B12: =YEARFRAC(A9,A10,1) -> 40.682404
A13: CAGR | B13: =(C10/C9)^(1/B12)-1 -> 0.07546018
A14: Marginal Tax Rate | B14: 0.27
A15: Beta Calculation
A16: Bottom-Up Beta | B16: =J32 -> 0.35754874
A17: Cost of Equity | B17: =B5+(B6-B5)*B16 -> 0.053128459
A19: Name | C19: Regression Beta | E19: Market Cap | G19: Debt | H19: Total capital | J19: Unlevered Beta
A20: Competitor
A21: Colgate Palmolive | C21: =E37 -> 0.32847875 | E21: =AVERAGE(65807,65631,74274) -> 68570.667 | G21: =AVERAGE(7991,7583,6853) -> 7475.6667 | H21: =G21+E21 -> 76046.333 | J21: =(C21/(G21*(1-$B$14)+E21))*E21 -> 0.30426374
A23: Peers
A24: Procter & Gamble | C24: =G37 -> 0.39232795 | E24: =AVERAGE(344995,357647,389234) -> 363958.67 | G24: =AVERAGE(24279,26361,22978) -> 24539.333 | H24: =E24+G24 -> 388498 | J24: =(C24/(G24*(1-$B$14)+E24)*E24) -> 0.37392376
A25: Kimberly-Clark | C25: =I37 -> 0.29535083 | E25: =AVERAGE(45815,41063,43700) -> 43526 | G25: =AVERAGE(8253,6917,6459) -> 7209.6667 | H25: =E25+G25 -> 50735.667 | J25: =(C25/(G25*(1-$B$14)+E25)*E25) -> 0.26349024
A26: Johnson & Johnson | C26: =K37 -> 0.40512848 | E26: =AVERAGE(464228,377317,349226) -> 396923.67 | G26: =AVERAGE(16140,6405,12112) -> 11552.333 | H26: =E26+G26 -> 408476 | J26: =(C26/(G26*(1-$B$14)+E26)*E26) -> 0.39670003
A27: Unilever | C27: =M37 -> 0.33243773 | E27: =AVERAGE(119234,109432,136147) -> 121604.33 | G27: =AVERAGE(23676,23657,24519) -> 23950.667 | H27: =E27+G27 -> 145555 | J27: =(C27/(G27*(1-$B$14)+E27)*E27) -> 0.29064891
G29: Average Unlevered Beta | J29: =AVERAGE(J24:J27) -> 0.33119074
C31: Regression Beta | E31: Market Cap | G31: Debt | H31: Total capital | J31: Relevered Beta
A32: Relevered Beta | C32: =J29 -> 0.33119074 | E32: =E21 -> 68570.667 | G32: =G21 -> 7475.6667 | H32: =H21 -> 76046.333 | J32: =(C32/E32)*(G32*(1-B14)+E32) -> 0.35754874
C36: NYSE | E36: Colgate | G36: Procter & Gamble | I36: Kimberly-Clark | K36: Johnson & Johnson | M36: Unilever
C37: =_xlfn.COVARIANCE.S($D$43:$D$249,D43:D249)/_xlfn.VAR.S($D$43:$D$249,D43:D249) -> 1.0024272 | E37: =_xlfn.COVARIANCE.S($D$43:$D$249,F43:F249)/_xlfn.VAR.S($D$43:$D$249,F43:F249) -> 0.32847875 | G37: =_xlfn.COVARIANCE.S($D$43:$D$249,H43:H249)/_xlfn.VAR.S($D$43:$D$249,H43:H249) -> 0.39232795 | I37: =_xlfn.COVARIANCE.S($D$43:$D$249,J43:J249)/_xlfn.VAR.S($D$43:$D$249,J43:J249) -> 0.29535083 | K37: =_xlfn.COVARIANCE.S($D$43:$D$249,L43:L249)/_xlfn.VAR.S($D$43:$D$249,L43:L249) -> 0.40512848 | M37: =_xlfn.COVARIANCE.S($D$43:$D$249,N43:N249)/_xlfn.VAR.S($D$43:$D$249,N43:N249) -> 0.33243773
A40: Date | C40: Price | D40: Returns | E40: Price | F40: Returns | G40: Price | H40: Returns | I40: Price | J40: Returns | K40: Price | L40: Returns | M40: Price | N40: Returns
A42: Sep 07, 2025 | C42: 21056.4 | E42: 82.29 | G42: 155.89 | I42: 127.01 | K42: 174.33 | M42: 62.6
A43: Aug 31, 2025 | C43: 20894.6 | D43: =C43/C42-1 -> -0.0076841245 | E43: 82.65 | F43: =E43/E42-1 -> 0.0043747721 | G43: 156.49 | H43: =G43/G42-1 -> 0.0038488678 | I43: 127.1 | J43: =I43/I42-1 -> 0.00070860562 | K43: 176.53 | L43: =K43/K42-1 -> 0.012619744 | M43: 63.25 | N43: =M43/M42-1 -> 0.010383387
A44: Aug 24, 2025 | C44: 20980.5 | D44: =C44/C43-1 -> 0.00411111 | E44: 83.22 | F44: =E44/E43-1 -> 0.0068965517 | G44: 155.03 | H44: =G44/G43-1 -> -0.0093296696 | I44: 128.02 | J44: =I44/I43-1 -> 0.007238395 | K44: 174.63 | L44: =K44/K43-1 -> -0.010763043 | M44: 61.79 | N44: =M44/M43-1 -> -0.023083004
A45: Aug 17, 2025 | C45: 20746.9 | D45: =C45/C44-1 -> -0.011134148 | E45: 84.25 | F45: =E45/E44-1 -> 0.012376832 | G45: 154.17 | H45: =G45/G44-1 -> -0.0055473134 | I45: 130.59 | J45: =I45/I44-1 -> 0.020074988 | K45: 175.98 | L45: =K45/K44-1 -> 0.0077306305 | M45: 60.86 | N45: =M45/M44-1 -> -0.015050979
A46: Aug 10, 2025 | C46: 20462.5 | D46: =C46/C45-1 -> -0.013708072 | E46: 84.16 | F46: =E46/E45-1 -> -0.0010682493 | G46: 153.27 | H46: =G46/G45-1 -> -0.0058377116 | I46: 131.62 | J46: =I46/I45-1 -> 0.0078872808 | K46: 171.81 | L46: =K46/K45-1 -> -0.023695875 | M46: 60.65 | N46: =M46/M45-1 -> -0.0034505422
A47: Aug 03, 2025 | C47: 20267.7 | D47: =C47/C46-1 -> -0.0095198534 | E47: 82.4 | F47: =E47/E46-1 -> -0.020912548 | G47: 150.02 | H47: =G47/G46-1 -> -0.021204411 | I47: 131.19 | J47: =I47/I46-1 -> -0.0032669807 | K47: 166.64 | L47: =K47/K46-1 -> -0.03009138 | M47: 59.82 | N47: =M47/M46-1 -> -0.013685078
A48: Jul 27, 2025 | C48: 20131.8 | D48: =C48/C47-1 -> -0.0067052502 | E48: 82.7 | F48: =E48/E47-1 -> 0.0036407767 | G48: 149.91 | H48: =G48/G47-1 -> -0.00073323557 | I48: 124.37 | J48: =I48/I47-1 -> -0.05198567 | K48: 164.23 | L48: =K48/K47-1 -> -0.014462314 | M48: 58.15 | N48: =M48/M47-1 -> -0.027917085
A49: Jul 20, 2025 | C49: 20513.5 | D49: =C49/C48-1 -> 0.018960053 | E49: 86.57 | F49: =E49/E48-1 -> 0.046795647 | G49: 154.89 | H49: =G49/G48-1 -> 0.033219932 | I49: 126.53 | J49: =I49/I48-1 -> 0.017367532 | K49: 162.78 | L49: =K49/K48-1 -> -0.0088290812 | M49: 59.58 | N49: =M49/M48-1 -> 0.024591574
A50: Jul 13, 2025 | C50: 20277.7 | D50: =C50/C49-1 -> -0.011494869 | E50: 86.5 | F50: =E50/E49-1 -> -0.0008085942 | G50: 151.9 | H50: =G50/G49-1 -> -0.019304022 | I50: 125.15 | J50: =I50/I49-1 -> -0.010906504 | K50: 154.8 | L50: =K50/K49-1 -> -0.049023222 | M50: 59.53 | N50: =M50/M49-1 -> -0.00083920779
A51: Jul 06, 2025 | C51: 20441.5 | D51: =C51/C50-1 -> 0.0080778392 | E51: 89.1 | F51: =E51/E50-1 -> 0.030057803 | G51: 155.95 | H51: =G51/G50-1 -> 0.026662278 | I51: 129.21 | J51: =I51/I50-1 -> 0.032441071 | K51: 154.21 | L51: =K51/K50-1 -> -0.0038113695 | M51: 60.46 | N51: =M51/M50-1 -> 0.015622375
A52: Jun 29, 2025 | C52: 20338.4 | D52: =C52/C51-1 -> -0.0050436612 | E52: 88.5 | F52: =E52/E51-1 -> -0.0067340067 | G52: 158.13 | H52: =G52/G51-1 -> 0.013978839 | I52: 127.68 | J52: =I52/I51-1 -> -0.011841189 | K52: 151.52 | L52: =K52/K51-1 -> -0.017443746 | M52: 60.61 | N52: =M52/M51-1 -> 0.0024809792
A53: Jun 22, 2025 | C53: 19765.4 | D53: =C53/C52-1 -> -0.028173308 | E53: 87.07 | F53: =E53/E52-1 -> -0.016158192 | G53: 157.17 | H53: =G53/G52-1 -> -0.0060709543 | I53: 126.3 | J53: =I53/I52-1 -> -0.010808271 | K53: 149.74 | L53: =K53/K52-1 -> -0.011747624 | M53: 60.37 | N53: =M53/M52-1 -> -0.0039597426
...

Sheet Revenue
A2: Particulars | C2: Historical | G2: Forecast
B3: Unit | C3: 2021 | D3: =C3+1 -> 2022 | E3: =D3+1 -> 2023 | F3: =E3+1 -> 2024 | G3: =F3+1 -> 2025 | H3: =G3+1 -> 2026 | I3: =H3+1 -> 2027 | J3: =I3+1 -> 2028 | K3: =J3+1 -> 2029
A5: North America | C5: 3694 | D5: 3816 | E5: 4091 | F5: 4113 | G5: =F5*(1+G8) -> 4108.0644 | H5: =G5*(1+H8) -> 4132.7128 | I5: =H5*(1+I8) -> 4187.2646 | J5: =I5*(1+J8) -> 4272.6848 | K5: =J5*(1+K8) -> 4400.8653
A6: Growth rate% | D6: 0.035 | E6: 0.022 | F6: 0.005
A7: Add/Less: Inorganic growth | D7: 0 | E7: 0.002 | F7: 0.001
A8: Organic | D8: =D6+D7 -> 0.035 | E8: =E6+E7 -> 0.024 | F8: =F6+F7 -> 0.006 | G8: =F8-($F$8+$K$8)/5 -> -0.0012 | H8: =G8+($F$8+$K$8)/5 -> 0.006 | I8: =H8+($F$8+$K$8)/5 -> 0.0132 | J8: =I8+($F$8+$K$8)/5 -> 0.0204 | K8: 0.03
A10: Latin America | C10: 3663 | D10: 3982 | E10: 4640 | F10: 4782 | G10: =F10*(1+G13) -> 5590.5538 | H10: =G10*(1+H13) -> 6544.0902 | I10: =H10*(1+I13) -> 7669.9445 | J10: =I10*(1+J13) -> 9000.8385 | K10: =J10*(1+K13) -> 10575.985
A11: Growth rate% | D11: 0.085 | E11: =E10/D10-1 -> 0.1652436 | F11: =F10/E10-1 -> 0.030603448
A12: Add/Less: Inorganic growth | D12: 0.002 | E12: -0.011 | F12: 0.137
A13: Organic | D13: =D11+D12 -> 0.087 | E13: =E11+E12 -> 0.1542436 | F13: =F11+F12 -> 0.16760345 | G13: =F13+($K$13-$F$13)/5 -> 0.16908276 | H13: =G13+($K$13-$F$13)/5 -> 0.17056207 | I13: =H13+($K$13-$F$13)/5 -> 0.17204138 | J13: =I13+($K$13-$F$13)/5 -> 0.17352069 | K13: 0.175
A15: Europe | C15: 2841 | D15: 2548 | E15: 2571 | F15: 2770 | G15: =F15*(1+G18) -> 2958.6964 | H15: =G15*(1+H18) -> 3165.3349 | I15: =H15*(1+I18) -> 3391.8485 | J15: =I15*(1+J18) -> 3640.4044 | K15: =J15*(1+K18) -> 3913.4347
A16: Growth rate% | D16: -0.105 | E16: 0.089 | F16: =F15/E15-1 -> 0.077401789
A17: Add/Less: Inorganic growth | D17: 0.105 | E17: -0.026 | F17: -0.011
A18: Organic | D18: =D16+D17 -> 0 | E18: =E16+E17 -> 0.063 | F18: =F16+F17 -> 0.066401789 | G18: =F18+($K$18-$F$18)/5 -> 0.068121431 | H18: =G18+($K$18-$F$18)/5 -> 0.069841074 | I18: =H18+($K$18-$F$18)/5 -> 0.071560716 | J18: =I18+($K$18-$F$18)/5 -> 0.073280358 | K18: 0.075
A20: Asia Pasific | C20: 2867 | D20: 2826 | E20: 2782 | F20: 2858 | G20: =F20*(1+G23) -> 2975.9062 | H20: =G20*(1+H23) -> 3101.4629 | I20: =H20*(1+I23) -> 3235.2209 | J20: =I20*(1+J23) -> 3377.7767 | K20: =J20*(1+K23) -> 3529.7766
A21: Growth rate% | D21: -0.015 | E21: -0.016 | F21: =F20/E20-1 -> 0.027318476
A22: Add/Less: Inorganic growth | D22: 0.065 | E22: 0.038 | F22: 0.013
A23: Organic | D23: =D21+D22 -> 0.05 | E23: =E21+E22 -> 0.022 | F23: =F21+F22 -> 0.040318476 | G23: =F23+($K$23-$F$23)/5 -> 0.041254781 | H23: =G23+($K$23-$F$23)/5 -> 0.042191086 | I23: =H23+($K$23-$F$23)/5 -> 0.04312739 | J23: =I23+($K$23-$F$23)/5 -> 0.044063695 | K23: 0.045
A25: Africa/Eurasia | C25: 1045 | D25: 1082 | E25: 1083 | F25: 1095 | G25: =F25*(1+G28) -> 1241.3624 | H25: =G25*(1+H28) -> 1409.2544 | I25: =H25*(1+I28) -> 1602.0857 | J25: =I25*(1+J28) -> 1823.8401 | K25: =J25*(1+K28) -> 2079.1777
A26: Growth rate% | D26: 0.035 | E26: 0.001 | F26: =F25/E25-1 -> 0.011080332
A27: Add/Less: Inorganic growth | D27: 0.085 | E27: 0.172 | F27: 0.121
A28: Organic | D28: =D26+D27 -> 0.12 | E28: =E26+E27 -> 0.173 | F28: =F26+F27 -> 0.13208033 | G28: =F28+($K$28-$F$28)/5 -> 0.13366427 | H28: =G28+($K$28-$F$28)/5 -> 0.1352482 | I28: =H28+($K$28-$F$28)/5 -> 0.13683213 | J28: =I28+($K$28-$F$28)/5 -> 0.13841607 | K28: 0.14
A30: Hill's Pet Nutrition | C30: 3311 | D30: 3713 | E30: 4290 | F30: 4483 | G30: =F30*(1+G33) -> 4676.6238 | H30: =G30*(1+H33) -> 4851.4968 | I30: =H30*(1+I33) -> 5004.7815 | J30: =I30*(1+J33) -> 5133.8932 | K30: =J30*(1+K33) -> 5236.5711
A31: Growth rate% | D31: 0.12 | E31: 0.155 | F31: =F30/E30-1 -> 0.044988345
A32: Add/Less: Inorganic growth | D32: =3.5%-2.5% -> 0.01 | E32: =0.5%-5.4% -> -0.049 | F32: 0.004
A33: Organic | D33: =D31+D32 -> 0.13 | E33: =E31+E32 -> 0.106 | F33: =F31+F32 -> 0.048988345 | G33: =F33+($K$33-$F$33)/5 -> 0.043190676 | H33: =G33+($K$33-$F$33)/5 -> 0.037393007 | I33: =H33+($K$33-$F$33)/5 -> 0.031595338 | J33: =I33+($K$33-$F$33)/5 -> 0.025797669 | K33: 0.02
A35: Total Revenue | C35: =SUM(C30,C25,C20,C15,C10,C5) -> 17421 | D35: =SUM(D30,D25,D20,D15,D10,D5) -> 17967 | E35: =SUM(E30,E25,E20,E15,E10,E5) -> 19457 | F35: =SUM(F30,F25,F20,F15,F10,F5) -> 20101 | G35: =SUM(G30,G25,G20,G15,G10,G5) -> 21551.207 | H35: =SUM(H30,H25,H20,H15,H10,H5) -> 23204.352 | I35: =SUM(I30,I25,I20,I15,I10,I5) -> 25091.146 | J35: =SUM(J30,J25,J20,J15,J10,J5) -> 27249.438 | K35: =SUM(K30,K25,K20,K15,K10,K5) -> 29735.811

Sheet P&L
A3: Particulars | C3: Historical | G3: Forecast
B4: Unit | C4: 2021 | D4: =C4+1 -> 2022 | E4: =D4+1 -> 2023 | F4: =E4+1 -> 2024 | G4: =F4+1 -> 2025 | H4: =G4+1 -> 2026 | I4: =H4+1 -> 2027 | J4: =I4+1 -> 2028 | K4: =J4+1 -> 2029
A6: Net sales | C6: =Revenue!C35 -> 17421 | D6: =Revenue!D35 -> 17967 | E6: =Revenue!E35 -> 19457 | F6: =Revenue!F35 -> 20101 | G6: =Revenue!G35 -> 21551.207 | H6: =Revenue!H35 -> 23204.352 | I6: =Revenue!I35 -> 25091.146 | J6: =Revenue!J35 -> 27249.438 | K6: =Revenue!K35 -> 29735.811
A7: Add/Less Extraordinary items | C7: 0 | D7: 0 | E7: 0 | F7: 0 | G7: 0 | H7: 0 | I7: 0 | J7: 0 | K7: 0
A8: Normalised Net sales | C8: =C6-C7 -> 17421 | D8: =D6-D7 -> 17967 | E8: =E6-E7 -> 19457 | F8: =F6-F7 -> 20101 | G8: =G6-G7 -> 21551.207 | H8: =H6-H7 -> 23204.352 | I8: =I6-I7 -> 25091.146 | J8: =J6-J7 -> 27249.438 | K8: =K6-K7 -> 29735.811
A9: Cost of sales | C9: 7046 | D9: 7719 | E9: 8131 | F9: 7940
A10: Add/Less Extraordinary items | C10: 0 | D10: 0 | E10: 0 | F10: 0
A11: Normalised cost of sales | C11: =C9-C10 -> 7046 | D11: =D9-D10 -> 7719 | E11: =E9-E10 -> 8131 | F11: =F9-F10 -> 7940 | G11: =G8-G14 -> 8918.4332 | H11: =H8-H14 -> 9602.5463 | I11: =I8-I14 -> 10383.349 | J11: =J8-J14 -> 11276.505 | K11: =K8-K14 -> 12305.429
A12: Gross profit | C12: =C6-C9 -> 10375 | D12: =D6-D9 -> 10248 | E12: =E6-E9 -> 11326 | F12: =F6-F9 -> 12161
A13: Add/Less Extraordinary items | C13: 0 | D13: 0 | E13: 1 | F13: 20
A14: Normalised Gross Profit | C14: =C12+C13 -> 10375 | D14: =D12+D13 -> 10248 | E14: =E12+E13 -> 11327 | F14: =F12+F13 -> 12181 | G14: =G8*G70 -> 12632.774 | H14: =H8*H70 -> 13601.806 | I14: =I8*I70 -> 14707.796 | J14: =J8*J70 -> 15972.933 | K14: =K8*K70 -> 17430.382
A16: Selling, general and administrative expenses | C16: 6407 | D16: 6565 | E16: 7151 | F16: 7729
A17: Add/Less Extraordinary items | C17: 0 | D17: -5 | E17: -2 | F17: -6
A18: Normalised SG&A | C18: =C16+C17 -> 6407 | D18: =D16+D17 -> 6560 | E18: =E16+E17 -> 7149 | F18: =F16+F17 -> 7723 | G18: =(G8*G71) -> 8022.4308 | H18: =(H8*H71) -> 8637.8136 | I18: =(I8*I71) -> 9340.172 | J18: =(J8*J71) -> 10143.596 | K18: =(K8*K71) -> 11069.147
A19: Depreciation & Amortization | G19: =Capex!G13 -> 608.19947 | H19: =Capex!H13 -> 622.28737 | I19: =Capex!I13 -> 640.44046 | J19: =Capex!J13 -> 662.96099 | K19: =Capex!K13 -> 690.49352
A20: Other (income) expense, net | C20: 65 | D20: 69 | E20: 191 | F20: 164
A21: Add/Less Extraordinary items | C21: 26 | D21: =-90-19+47 -> -62 | E21: =(-24)+(-25) -> -49 | F21: -59
A22: Normalised other (income) expenses,net | C22: =C20+C21 -> 91 | D22: =D20+D21 -> 7 | E22: =E20+E21 -> 142 | F22: =F20+F21 -> 105 | G22: =G8*G72 -> 134.92958 | H22: =H8*H72 -> 145.27972 | I22: =I8*I72 -> 157.09272 | J22: =J8*J72 -> 170.60553 | K22: =K8*K72 -> 186.17242
A23: Goodwill and intangible assets impairment charges | C23: 571 | D23: 721 | E23: 0 | F23: 0 | G23: 0 | H23: 0 | I23: 0 | J23: 0 | K23: 0
A24: Operating profit | C24: =C12-(C16+C20+C23) -> 3332 | D24: =D12-(D16+D20+D23) -> 2893 | E24: =E12-(E16+E20) -> 3984 | F24: =F12-(F16+F20) -> 4268
A25: Add/Less Extraordinary items | C25: -26 | D25: =95+721-47+19 -> 788 | E25: 27 | F25: 85
A26: Normalised operating Profit | C26: =C24+C25 -> 3306 | D26: =D24+D25 -> 3681 | E26: =E24+E25 -> 4011 | F26: =F24+F25 -> 4353 | G26: =G14-SUM(G18,G19,G22) -> 3867.2139 | H26: =H14-SUM(H18,H19,H22) -> 4196.4249 | I26: =I14-SUM(I18,I19,I22) -> 4570.0913 | J26: =J14-SUM(J18,J19,J22) -> 4995.7707 | K26: =K14-SUM(K18,K19,K22) -> 5484.5687
A28: Non-service related postretirement costs | C28: 70 | D28: 80 | E28: 360 | F28: 87
A29: Add/Less Extraordinary items | C29: 0 | D29: -15 | E29: =-267-5 -> -272 | F29: 0
A30: Normalised Non-service related postretirement cossts | C30: =C28+C29 -> 70 | D30: =D28+D29 -> 65 | E30: =E28+E29 -> 88 | F30: =F28+F29 -> 87 | G30: =F30 -> 87 | H30: =G30 -> 87 | I30: =H30 -> 87 | J30: =I30 -> 87 | K30: =J30 -> 87
A32: Interest Expense,(income),net | C32: 175 | D32: =167-14 -> 153 | E32: =287-55 -> 232 | F32: =292-67 -> 225 | G32: =Debt!C12+Debt!C24 -> 223.33609 | H32: =Debt!D12+Debt!D24 -> 210.26901 | I32: =Debt!E12+Debt!E24 -> 214.56881 | J32: =Debt!F12+Debt!F24 -> 219.17593 | K32: =Debt!G12+Debt!G24 -> 224.07331
A33: Add/Less Extraordinary items | C33: -75 | D33: 0 | E33: 0 | F33: 0 | G33: 0 | H33: 0 | I33: 0 | J33: 0 | K33: 0
A34: Normalised Interest Expenses | C34: =C32+C33 -> 100 | D34: =D32+D33 -> 153 | E34: =E32+E33 -> 232 | F34: =F32+F33 -> 225 | G34: =G32+G33 -> 223.33609 | H34: =H32+H33 -> 210.26901 | I34: =I32+I33 -> 214.56881 | J34: =J32+J33 -> 219.17593 | K34: =K32+K33 -> 224.07331
A37: Income before income taxe | C37: =C24-(C28+C32) -> 3087 | D37: =D24-(D28+D32) -> 2660 | E37: =E24-(E28+E32) -> 3392 | F37: =F24-(F28+F32) -> 3956
A38: Add/Less Extraordinary items | C38: =571+75-26 -> 620 | D38: =721+110-47+19 -> 803 | E38: =267+32+25 -> 324 | F38: 85
A39: Normalised Income before Income Taxes | C39: =C37+C38 -> 3707 | D39: =D37+D38 -> 3463 | E39: =E37+E38 -> 3716 | F39: =F37+F38 -> 4041 | G39: =G26-(G30+G34) -> 3556.8778 | H39: =H26-(H30+H34) -> 3899.1559 | I39: =I26-(I30+I34) -> 4268.5225 | J39: =J26-(J30+J34) -> 4689.5947 | K39: =K26-(K30+K34) -> 5173.4954
A41: Provision for income taxes | C41: 749 | D41: 693 | E41: 937 | F41: 907
A42: Add/Less Extraordinary items | C42: =53+20-6 -> 67 | D42: =101+22-11+3 -> 115 | E42: =(55+6+6)-126 -> -59 | F42: 12
A43: Normalised Provision for Income taxes | C43: =C41+C42 -> 816 | D43: =D41+D42 -> 808 | E43: =E41+E42 -> 878 | F43: =F41+F42 -> 919 | G43: =G39*G73 -> 826.40288 | H43: =H39*H73 -> 905.92759 | I43: =I39*I73 -> 991.74599 | J43: =J39*J73 -> 1089.5777 | K43: =K39*K73 -> 1202.0069
A45: Net income including noncontrolling interests | C45: =C37-C41 -> 2338 | D45: =D37-D41 -> 1967 | E45: =E37-E41 -> 2455 | F45: =F37-F41 -> 3049
A46: Add/Less Extraordinary items | C46: =518+55-20 -> 553 | D46: =620+88-36+16 -> 688 | E46: =212+126+26+19 -> 383 | F46: 73
A47: Normalised Net Income Including non controlling interests | C47: =C45+C46 -> 2891 | D47: =D45+D46 -> 2655 | E47: =E45+E46 -> 2838 | F47: =F45+F46 -> 3122 | G47: =G39-G43 -> 2730.4749 | H47: =H39-H43 -> 2993.2283 | I47: =I39-I43 -> 3276.7765 | J47: =J39-J43 -> 3600.0171 | K47: =K39-K43 -> 3971.4885
M48: =G47-G55 -> 136.52374 | N48: =H47-H55 -> 149.66142 | O48: =I47-I55 -> 163.83882 | P48: =J47-J55 -> 180.00085 | Q48: =K47-K55 -> 198.57443
A49: Less: Net income attributable to noncontrolling interests | C49: 172 | D49: 182 | E49: 155 | F49: 160
A50: Add/Less Extraordinary items | C50: 0 | D50: =-21+1 -> -20 | E50: 1 | F50: 0
...

Sheet Balance Sheet
A1: Particulars | C1: Historical | G1: Forecast
B2: Unit | C2: 2021 | D2: =C2+1 -> 2022 | E2: =D2+1 -> 2023 | F2: =E2+1 -> 2024 | G2: =F2+1 -> 2025 | H2: =G2+1 -> 2026 | I2: =H2+1 -> 2027 | J2: =I2+1 -> 2028 | K2: =J2+1 -> 2029
A3: Assets
A4: Current Assets
A5: Cash and cash equivalents | C5: 832 | D5: 775 | E5: 966 | F5: 1096 | G5: =CFS!C33 -> 1614.9947 | H5: =CFS!D33 -> 3277.6487 | I5: =CFS!E33 -> 4991.5686 | J5: =CFS!F33 -> 6769.7558 | K5: =CFS!G33 -> 8623.6747
A6: Receivables | C6: 1297 | D6: 1504 | E6: 1586 | F6: 1521 | G6: =G48 -> 1576.1915 | H6: =H48 -> 1638.3712 | I6: =I48 -> 1708.089 | J6: =J48 -> 1786.0517 | K6: =K48 -> 1873.7634
A7: Inventories | C7: 1692 | D7: 2074 | E7: 1934 | F7: 1987 | G7: =G52 -> 2231.8548 | H7: =H52 -> 2403.0554 | I7: =I52 -> 2598.4527 | J7: =J52 -> 2821.9666 | K7: =K52 -> 3079.4568
A8: Other current assets | C8: 576 | D8: 760 | E8: 793 | F8: 713 | G8: =G56 -> 764.4401 | H8: =H56 -> 823.0786 | I8: =I56 -> 890.00482 | J8: =J56 -> 966.56132 | K8: =K56 -> 1054.7551
A9: Total current assets | C9: =SUM(C5:C8) -> 4397 | D9: =SUM(D5:D8) -> 5113 | E9: =SUM(E5:E8) -> 5279 | F9: =SUM(F5:F8) -> 5317 | G9: =SUM(G5:G8) -> 6187.4811 | H9: =SUM(H5:H8) -> 8142.1539 | I9: =SUM(I5:I8) -> 10188.115 | J9: =SUM(J5:J8) -> 12344.335 | K9: =SUM(K5:K8) -> 14631.65
A10: Property, plant and equipment, net | C10: 3730 | D10: 4307 | E10: 4582 | F10: 4422 | G10: =Capex!G8 -> 4076.6874 | H10: =Capex!H8 -> 3791.5853 | I10: =Capex!I8 -> 3566.0059 | J10: =Capex!J8 -> 3401.3568 | K10: =Capex!K8 -> 3304.9425
A11: Goodwill | C11: 3284 | D11: 3352 | E11: 3410 | F11: 3272 | G11: =F11 -> 3272 | H11: =G11 -> 3272 | I11: =H11 -> 3272 | J11: =I11 -> 3272 | K11: =J11 -> 3272
A12: Other intangible assets, net | C12: 2462 | D12: 1920 | E12: 1887 | F12: 1756 | G12: =Capex!G19 -> 1688 | H12: =Capex!H19 -> 1620 | I12: =Capex!I19 -> 1552 | J12: =Capex!J19 -> 1484 | K12: =Capex!K19 -> 1416
A13: Deferred income taxes | C13: 193 | D13: 135 | E13: 214 | F13: 195 | G13: =F13 -> 195 | H13: =G13 -> 195 | I13: =H13 -> 195 | J13: =I13 -> 195 | K13: =J13 -> 195
A14: Other assets | C14: 974 | D14: 904 | E14: 1021 | F14: 1084 | G14: =F14 -> 1084 | H14: =G14 -> 1084 | I14: =H14 -> 1084 | J14: =I14 -> 1084 | K14: =J14 -> 1084
A15: Total assets | C15: =SUM(C9:C14) -> 15040 | D15: =SUM(D9:D14) -> 15731 | E15: =SUM(E9:E14) -> 16393 | F15: =SUM(F9:F14) -> 16046 | G15: =SUM(G9:G14) -> 16503.168 | H15: =SUM(H9:H14) -> 18104.739 | I15: =SUM(I9:I14) -> 19857.121 | J15: =SUM(J9:J14) -> 21780.692 | K15: =SUM(K9:K14) -> 23903.593
A16: Liabilities and Shareholders’ Equity
A17: Current Liabilities
A18: Debt payable within one-year | C18: 12 | D18: 14 | E18: 20 | F18: 652 | G18: =Debt!D7 -> 1035 | H18: =Debt!E7 -> 509 | I18: =Debt!F7 -> 612 | J18: =Debt!G7 -> 519 | K18: =Debt!H7 -> 0
A19: Notes & Loans Payable | C19: 39 | D19: 11 | E19: 310 | F19: 8 | G19: =Debt!C20 -> 131.52288 | H19: =Debt!D20 -> 134.13416 | I19: =Debt!E20 -> 136.95531 | J19: =Debt!F20 -> 139.95486 | K19: =Debt!G20 -> 143.14273
A20: Accounts payable | C20: 1479 | D20: 1551 | E20: 1698 | F20: 1805 | G20: =G60 -> 2051.8613 | H20: =H60 -> 2235.5633 | I20: =I60 -> 2445.7891 | J20: =J60 -> 2687.0657 | K20: =K60 -> 2965.9603
A21: Accrued income taxes | C21: 436 | D21: 317 | E21: 336 | F21: 403 | G21: =G64 -> 339.32435 | H21: =H64 -> 371.97752 | I21: =I64 -> 407.2149 | J21: =J64 -> 447.38498 | K21: =K64 -> 493.54886
A22: Other accruals | C22: 2085 | D22: 2111 | E22: 2377 | F22: 2891 | G22: =G70 -> 3247.2532 | H22: =H70 -> 3496.3428 | I22: =I70 -> 3780.6376 | J22: =J70 -> 4105.8408 | K22: =K70 -> 4480.4779
A23: Total current liabilities | C23: =SUM(C18:C22) -> 4051 | D23: =SUM(D18:D22) -> 4004 | E23: =SUM(E18:E22) -> 4741 | F23: =SUM(F18:F22) -> 5759 | G23: =SUM(G18:G22) -> 6804.9617 | H23: =SUM(H18:H22) -> 6747.0177 | I23: =SUM(I18:I22) -> 7382.5969 | J23: =SUM(J18:J22) -> 7899.2463 | K23: =SUM(K18:K22) -> 8083.1298
A24: Long-term debt | C24: 7194 | D24: 8741 | E24: 8219 | F24: 7289 | G24: =Debt!C8-Debt!D7 -> 5773.5497 | H24: =Debt!D8-Debt!E7 -> 6434.7275 | I24: =Debt!E8-Debt!F7 -> 6477.7703 | J24: =Debt!F8-Debt!G7 -> 6726.0483 | K24: =Debt!G8-Debt!H7 -> 7410.0747
A25: Deferred income taxes | C25: 395 | D25: 383 | E25: 361 | F25: 343 | G25: =F25 -> 343 | H25: =G25 -> 343 | I25: =H25 -> 343 | J25: =I25 -> 343 | K25: =J25 -> 343
A26: Other liabilities | C26: 2429 | D26: 1797 | E26: 2115 | F26: 2111 | G26: =F26 -> 2111 | H26: =G26 -> 2111 | I26: =H26 -> 2111 | J26: =I26 -> 2111 | K26: =J26 -> 2111
A27: Total liabilities | C27: =SUM(C23:C26) -> 14069 | D27: =SUM(D23:D26) -> 14925 | E27: =SUM(E23:E26) -> 15436 | F27: =SUM(F23:F26) -> 15502 | G27: =SUM(G23:G26) -> 15032.511 | H27: =SUM(H23:H26) -> 15635.745 | I27: =SUM(I23:I26) -> 16314.367 | J27: =SUM(J23:J26) -> 17079.295 | K27: =SUM(K23:K26) -> 17947.205
A28: Commitments and contingent liabilities
A29: Shareholders’ Equity
A30: Common stock | C30: 1466 | D30: 1466 | E30: 1466 | F30: 1466 | G30: =F30 -> 1466 | H30: =G30 -> 1466 | I30: =H30 -> 1466 | J30: =I30 -> 1466 | K30: =J30 -> 1466
A31: Additional paid-in capital | C31: 3269 | D31: 3546 | E31: 3808 | F31: 4181 | G31: =F31 -> 4181 | H31: =G31 -> 4181 | I31: =H31 -> 4181 | J31: =I31 -> 4181 | K31: =J31 -> 4181
A32: Retained earning | C32: 24350 | D32: 24573 | E32: 25289 | F32: 26145 | G32: =F32+'P&L'!G55-'P&L'!G75 -> 26935.133 | H32: =G32+'P&L'!H55-'P&L'!H75 -> 27783.809 | I32: =H32+'P&L'!I55-'P&L'!I75 -> 28693.73 | J32: =I32+'P&L'!J55-'P&L'!J75 -> 29672.373 | K32: =J32+'P&L'!K55-'P&L'!K75 -> 30728.789
A33: Accumulated other comprehensive income (loss) | C33: -4386 | D33: -4055 | E33: -3937 | F33: -4222 | G33: =F33 -> -4222 | H33: =G33 -> -4222 | I33: =H33 -> -4222 | J33: =I33 -> -4222 | K33: =J33 -> -4222
A34: Umearned compensation | C34: -1 | D34: -1 | E34: 0 | F34: 0 | G34: =F34 -> 0 | H34: =G34 -> 0 | I34: =H34 -> 0 | J34: =I34 -> 0 | K34: =J34 -> 0
A35: Treasury stock, at cost | C35: -24089 | D35: -25128 | E35: -26017 | F35: -27358 | G35: =F35 -> -27358 | H35: =G35 -> -27358 | I35: =H35 -> -27358 | J35: =I35 -> -27358 | K35: =J35 -> -27358
A36: Total Colgate-Palmolive Company shareholders’ equity | C36: =SUM(C30:C35) -> 609 | D36: =SUM(D30:D35) -> 401 | E36: =SUM(E30:E35) -> 609 | F36: 212 | G36: =F36+'P&L'!G55-'P&L'!G75 -> 1002.1333 | H36: =G36+'P&L'!H55-'P&L'!H75 -> 1850.8088 | I36: =H36+'P&L'!I55-'P&L'!I75 -> 2760.7299 | J36: =I36+'P&L'!J55-'P&L'!J75 -> 3739.3728 | K36: =J36+'P&L'!K55-'P&L'!K75 -> 4795.7887
A37: Noncontrolling interests | C37: 362 | D37: 405 | E37: 348 | F37: 332 | G37: =F37+'P&L'!G51 -> 468.52374 | H37: =G37+'P&L'!H51 -> 618.18516 | I37: =H37+'P&L'!I51 -> 782.02399 | J37: =I37+'P&L'!J51 -> 962.02484 | K37: =J37+'P&L'!K51 -> 1160.5993
A38: Total equity | C38: =C36+C37 -> 971 | D38: =D36+D37 -> 806 | E38: =E36+E37 -> 957 | F38: =F36+F37 -> 544 | G38: =G36+G37 -> 1470.657 | H38: =H36+H37 -> 2468.994 | I38: =I36+I37 -> 3542.7539 | J38: =J36+J37 -> 4701.3976 | K38: =K36+K37 -> 5956.388
A39: Total liabilities and equity | C39: =C27+C38 -> 15040 | D39: =D27+D38 -> 15731 | E39: =E27+E38 -> 16393 | F39: =F27+F38 -> 16046 | G39: =G27+G38 -> 16503.168 | H39: =H27+H38 -> 18104.739 | I39: =I27+I38 -> 19857.121 | J39: =J27+J38 -> 21780.692 | K39: =K27+K38 -> 23903.593
A41: check | C41: =C39-C15 -> 0 | D41: =D39-D15 -> 0 | E41: =E39-E15 -> 0 | F41: =F39-F15 -> 0 | G41: =G15-G39 -> 0 | H41: =H15-H39 -> 0 | I41: =I15-I39 -> 0 | J41: =J15-J39 -> 0 | K41: =K15-K39 -> 0
...

Sheet CFS
A1: Particulars | C1: Forecast
B2: Unit | C2: 2025 | D2: =C2+1 -> 2026 | E2: =D2+1 -> 2027 | F2: =E2+1 -> 2028 | G2: =F2+1 -> 2029
A3: Cash Flow from Operations
A4: Net income | C4: ='P&L'!G47 -> 2730.4749 | D4: ='P&L'!H47 -> 2993.2283 | E4: ='P&L'!I47 -> 3276.7765 | F4: ='P&L'!J47 -> 3600.0171 | G4: ='P&L'!K47 -> 3971.4885
A5: Add/Less:Non Cash Items
A6: Depreciation & Amortization | C6: =Capex!G13 -> 608.19947 | D6: =Capex!H13 -> 622.28737 | E6: =Capex!I13 -> 640.44046 | F6: =Capex!J13 -> 662.96099 | G6: =Capex!K13 -> 690.49352
A7: Other Income | C7: =-'P&L'!G22 -> -134.92958 | D7: =-'P&L'!H22 -> -145.27972 | E7: =-'P&L'!I22 -> -157.09272 | F7: =-'P&L'!J22 -> -170.60553 | G7: =-'P&L'!K22 -> -186.17242
A8: Interest expenses | C8: ='P&L'!G34 -> 223.33609 | D8: ='P&L'!H34 -> 210.26901 | E8: ='P&L'!I34 -> 214.56881 | F8: ='P&L'!J34 -> 219.17593 | G8: ='P&L'!K34 -> 224.07331
A9: Cash flow from operations before working capital | C9: =C4+SUM(C6:C8) -> 3427.0809 | D9: =D4+SUM(D6:D8) -> 3680.505 | E9: =E4+SUM(E6:E8) -> 3974.693 | F9: =F4+SUM(F6:F8) -> 4311.5485 | G9: =G4+SUM(G6:G8) -> 4699.8829
A10: Cash effects to changes in:
A11: Receivables | C11: =-('Balance Sheet'!G6-'Balance Sheet'!F6) -> -55.19151 | D11: =-('Balance Sheet'!H6-'Balance Sheet'!G6) -> -62.179739 | E11: =-('Balance Sheet'!I6-'Balance Sheet'!H6) -> -69.717777 | F11: =-('Balance Sheet'!J6-'Balance Sheet'!I6) -> -77.962677 | G11: =-('Balance Sheet'!K6-'Balance Sheet'!J6) -> -87.711711
A12: Inventories | C12: =-('Balance Sheet'!G7-'Balance Sheet'!F7) -> -244.85475 | D12: =-('Balance Sheet'!H7-'Balance Sheet'!G7) -> -171.20061 | E12: =-('Balance Sheet'!I7-'Balance Sheet'!H7) -> -195.39739 | F12: =-('Balance Sheet'!J7-'Balance Sheet'!I7) -> -223.5139 | G12: =-('Balance Sheet'!K7-'Balance Sheet'!J7) -> -257.49015
A13: Other current assets | C13: =-('Balance Sheet'!G8-'Balance Sheet'!F8) -> -51.440102 | D13: =-('Balance Sheet'!H8-'Balance Sheet'!G8) -> -58.638498 | E13: =-('Balance Sheet'!I8-'Balance Sheet'!H8) -> -66.926218 | F13: =-('Balance Sheet'!J8-'Balance Sheet'!I8) -> -76.5565 | G13: =-('Balance Sheet'!K8-'Balance Sheet'!J8) -> -88.19382
A14: Accrued income tax | C14: ='Balance Sheet'!G21-'Balance Sheet'!F21 -> -63.675648 | D14: ='Balance Sheet'!H21-'Balance Sheet'!G21 -> 32.653165 | E14: ='Balance Sheet'!I21-'Balance Sheet'!H21 -> 35.237383 | F14: ='Balance Sheet'!J21-'Balance Sheet'!I21 -> 40.170082 | G14: ='Balance Sheet'!K21-'Balance Sheet'!J21 -> 46.16388 | L14: =C4-2141 -> 589.47489
A15: Accounts Payable | C15: =+('Balance Sheet'!G20-'Balance Sheet'!F20) -> 246.86126 | D15: =+('Balance Sheet'!H20-'Balance Sheet'!G20) -> 183.70205 | E15: =+('Balance Sheet'!I20-'Balance Sheet'!H20) -> 210.22579 | F15: =+('Balance Sheet'!J20-'Balance Sheet'!I20) -> 241.2766 | G15: =+('Balance Sheet'!K20-'Balance Sheet'!J20) -> 278.89463
A16: Other accurals | C16: =+('Balance Sheet'!G22-'Balance Sheet'!F22) -> 356.25319 | D16: =+('Balance Sheet'!H22-'Balance Sheet'!G22) -> 249.08956 | E16: =+('Balance Sheet'!I22-'Balance Sheet'!H22) -> 284.29484 | F16: =+('Balance Sheet'!J22-'Balance Sheet'!I22) -> 325.20316 | G16: =+('Balance Sheet'!K22-'Balance Sheet'!J22) -> 374.63715
A17: Net Cash Provided by Operations | C17: =C9+SUM(C11:C16) -> 3615.0333 | D17: =D9+SUM(D11:D16) -> 3853.9309 | E17: =E9+SUM(E11:E16) -> 4172.4097 | F17: =F9+SUM(F11:F16) -> 4540.1652 | G17: =G9+SUM(G11:G16) -> 4966.1829
A19: Investing Activities
A20: Capital expenditures | C20: =-Capex!G5 -> -194.88683 | D20: =-Capex!H5 -> -269.1853 | E20: =-Capex!I5 -> -346.86105 | F20: =-Capex!J5 -> -430.31191 | G20: =-Capex!K5 -> -526.07918
A21: Other income | C21: =+'P&L'!G22 -> 134.92958 | D21: =+'P&L'!H22 -> 145.27972 | E21: =+'P&L'!I22 -> 157.09272 | F21: =+'P&L'!J22 -> 170.60553 | G21: =+'P&L'!K22 -> 186.17242
A22: Net cash used in Investing Activities | C22: =SUM(C20:C21) -> -59.957257 | D22: =SUM(D20:D21) -> -123.90558 | E22: =SUM(E20:E21) -> -189.76833 | F22: =SUM(F20:F21) -> -259.70638 | G22: =SUM(G20:G21) -> -339.90676
A24: Financing Activities
A25: Debt taken | C25: =Debt!C6+Debt!C18 -> -356.92737 | D25: =Debt!D6+Debt!D18 -> 1172.7891 | E25: =Debt!E6+Debt!E18 -> 657.86388 | F25: =Debt!F6+Debt!F18 -> 770.27761 | G25: =Debt!G6+Debt!G18 -> 687.21424
A26: Debt repaid | C26: =-Debt!C7 -> -652 | D26: =-Debt!D7 -> -1035 | E26: =-Debt!E7 -> -509 | F26: =-Debt!F7 -> -612 | G26: =-Debt!G7 -> -519
A27: Interest paid | C27: =-C8 -> -223.33609 | D27: =-D8 -> -210.26901 | E27: =-E8 -> -214.56881 | F27: =-F8 -> -219.17593 | G27: =-G8 -> -224.07331
A28: Dividends Paid | C28: =-'P&L'!G75 -> -1803.8179 | D28: =-'P&L'!H75 -> -1994.8914 | E28: =-'P&L'!I75 -> -2203.0165 | F28: =-'P&L'!J75 -> -2441.3734 | G28: =-'P&L'!K75 -> -2716.4982
A29: Net Cash Used in Financing Activities | C29: =SUM(C25:C28) -> -3036.0813 | D29: =SUM(D25:D28) -> -2067.3714 | E29: =SUM(E25:E28) -> -2268.7215 | F29: =SUM(F25:F28) -> -2502.2717 | G29: =SUM(G25:G28) -> -2772.3572
A31: Total cash generated during year | C31: =C17+C22+C29 -> 518.99472 | D31: =D17+D22+D29 -> 1662.654 | E31: =E17+E22+E29 -> 1713.9199 | F31: =F17+F22+F29 -> 1778.1871 | G31: =G17+G22+G29 -> 1853.9189
A32: Add:Opening balance | C32: =1096 -> 1096 | D32: =C33 -> 1614.9947 | E32: =D33 -> 3277.6487 | F32: =E33 -> 4991.5686 | G32: =F33 -> 6769.7558
A33: Closing Balance | C33: =C31+C32 -> 1614.9947 | D33: =D31+D32 -> 3277.6487 | E33: =E31+E32 -> 4991.5686 | F33: =F31+F32 -> 6769.7558 | G33: =G31+G32 -> 8623.6747

Sheet Debt
A2: Particulars | C2: Forecast
B3: Unit | C3: 2025 | D3: =C3+1 -> 2026 | E3: =D3+1 -> 2027 | F3: =E3+1 -> 2028 | G3: =F3+1 -> 2029
A4: Long-term debt | B4: $
A5: Opening Balance | C5: =7289+652 -> 7941 | D5: =C8 -> 6808.5497 | E5: =D8 -> 6943.7275 | F5: =E8 -> 7089.7703 | G5: =F8 -> 7245.0483
A6: Add:Loan taken | C6: =C8+C7-C5 -> -480.45026 | D6: =D8+D7-D5 -> 1170.1778 | E6: =E8+E7-E5 -> 655.04273 | F6: =F8+F7-F5 -> 767.27806 | G6: =G8+G7-G5 -> 684.02637
A7: Less:Loan Repaid | C7: 652 | D7: 1035 | E7: 509 | F7: 612 | G7: 519
A8: closing Balance | C8: =C13*'P&L'!G77 -> 6808.5497 | D8: =D13*'P&L'!H77 -> 6943.7275 | E8: =E13*'P&L'!I77 -> 7089.7703 | F8: =F13*'P&L'!J77 -> 7245.0483 | G8: =G13*'P&L'!K77 -> 7410.0747
A11: Average Interest Rate | C11: 0.03 | D11: 0.03 | E11: 0.03 | F11: 0.03 | G11: 0.03
A12: Interest Expenses | C12: =AVERAGE(C8,C5)*C11 -> 221.24325 | D12: =AVERAGE(D8,D5)*D11 -> 206.28416 | E12: =AVERAGE(E8,E5)*E11 -> 210.50247 | F12: =AVERAGE(F8,F5)*F11 -> 215.02228 | G12: =AVERAGE(G8,G5)*G11 -> 219.82684
A13: Total Long term debt/EBITDA | C13: ='Balance Sheet'!G73 -> 1.5213231 | D13: ='Balance Sheet'!H73 -> 1.4409923 | E13: ='Balance Sheet'!I73 -> 1.3606616 | F13: ='Balance Sheet'!J73 -> 1.2803308 | G13: ='Balance Sheet'!K73 -> 1.2
A16: Loans & Notes Payable
A17: Opening Balance | C17: 8 | D17: =C20 -> 131.52288 | E17: =D20 -> 134.13416 | F17: =E20 -> 136.95531 | G17: =F20 -> 139.95486
A18: Add:Loan taken | C18: =IF(C20>C17,C20-C17,0) -> 123.52288 | D18: =IF(D20>D17,D20-D17,0) -> 2.6112714 | E18: =IF(E20>E17,E20-E17,0) -> 2.8211531 | F18: =IF(F20>F17,F20-F17,0) -> 2.9995548 | G18: =IF(G20>G17,G20-G17,0) -> 3.187866
A19: Less:Loan Repaid | C19: =IF(C20<C17,C20-C17,0) -> 0 | D19: =IF(D20<D17,D20-D17,0) -> 0 | E19: =IF(E20<E17,E20-E17,0) -> 0 | F19: =IF(F20<F17,F20-F17,0) -> 0 | G19: =IF(G20<G17,G20-G17,0) -> 0
A20: Closing Balance | C20: =C8*'Balance Sheet'!G77 -> 131.52288 | D20: =D8*'Balance Sheet'!H77 -> 134.13416 | E20: =E8*'Balance Sheet'!I77 -> 136.95531 | F20: =F8*'Balance Sheet'!J77 -> 139.95486 | G20: =G8*'Balance Sheet'!K77 -> 143.14273
A23: Average Interest rate | C23: 0.03 | D23: 0.03 | E23: 0.03 | F23: 0.03 | G23: 0.03
A24: Interest Expenses | C24: =AVERAGE(C20,C17)*C23 -> 2.0928433 | D24: =AVERAGE(D20,D17)*D23 -> 3.9848556 | E24: =AVERAGE(E20,E17)*E23 -> 4.066342 | F24: =AVERAGE(F20,F17)*F23 -> 4.1536526 | G24: =AVERAGE(G20,G17)*G23 -> 4.2464639

Sheet Capex
A1: Particulars | C1: Historical | G1: Forecast
B2: Unit | C2: 2021 | D2: =C2+1 -> 2022 | E2: =D2+1 -> 2023 | F2: =E2+1 -> 2024 | G2: =F2+1 -> 2025 | H2: =G2+1 -> 2026 | I2: =H2+1 -> 2027 | J2: =I2+1 -> 2028 | K2: =J2+1 -> 2029
A3: Property,plant & Equipment
A4: Opening Gross Block | C4: 8751 | D4: =C6 -> 8899 | E4: =D6 -> 9583 | F4: =E6 -> 10286 | G4: =F6 -> 10127 | H4: =G6 -> 10321.887 | I4: =H6 -> 10591.072 | J4: =I6 -> 10937.933 | K4: =J6 -> 11368.245
A5: Add:Purchases | C5: =C6-C4 -> 148 | D5: =D6-D4 -> 684 | E5: =E6-E4 -> 703 | F5: =F6-F4 -> -159 | G5: =G6-G4 -> 194.88683 | H5: =H6-H4 -> 269.1853 | I5: =I6-I4 -> 346.86105 | J5: =J6-J4 -> 430.31191 | K5: =K6-K4 -> 526.07918
A6: Closing Gross Block | C6: 8899 | D6: 9583 | E6: 10286 | F6: 10127 | G6: =Revenue!G35/Capex!G15 -> 10321.887 | H6: =Revenue!H35/Capex!H15 -> 10591.072 | I6: =Revenue!I35/Capex!I15 -> 10937.933 | J6: =Revenue!J35/Capex!J15 -> 11368.245 | K6: =Revenue!K35/Capex!K15 -> 11894.324
A7: Less: accumulated Depreciation | C7: 5169 | D7: 5276 | E7: 5704 | F7: 5705 | G7: =G12+F7 -> 6245.1995 | H7: =H12+G7 -> 6799.4868 | I7: =I12+H7 -> 7371.9273 | J7: =J12+I7 -> 7966.8883 | K7: =K12+J7 -> 8589.3818
A8: Net Block | C8: 3730 | D8: 4307 | E8: 4582 | F8: 4422 | G8: =G6-G7 -> 4076.6874 | H8: =H6-H7 -> 3791.5853 | I8: =I6-I7 -> 3566.0059 | J8: =J6-J7 -> 3401.3568 | K8: =K6-K7 -> 3304.9425
A12: Depreciation | C12: =C13-C17 -> 467 | D12: =D13-D17 -> 465 | E12: =E13-E17 -> 495 | F12: =F13-F17 -> 530 | G12: =G6*G14 -> 540.19947 | H12: =H6*H14 -> 554.28737 | I12: =I6*I14 -> 572.44046 | J12: =J6*J14 -> 594.96099 | K12: =K6*K14 -> 622.49352
A13: Depreciation & Amortization | C13: 556 | D13: 545 | E13: 567 | F13: 605 | G13: =G12+G17 -> 608.19947 | H13: =H12+H17 -> 622.28737 | I13: =I12+I17 -> 640.44046 | J13: =J12+J17 -> 662.96099 | K13: =K12+K17 -> 690.49352
A14: Rate of Depreciation | C14: =C12/C6 -> 0.052477806 | D14: =D12/D6 -> 0.048523427 | E14: =E12/E6 -> 0.048123663 | F14: =F12/F6 -> 0.052335341 | G14: =F14 -> 0.052335341 | H14: =G14 -> 0.052335341 | I14: =H14 -> 0.052335341 | J14: =I14 -> 0.052335341 | K14: =J14 -> 0.052335341
A15: Fixed Assets Tirnover Ratio | C15: =Revenue!C35/Capex!C6 -> 1.9576357 | D15: =Revenue!D35/Capex!D6 -> 1.8748826 | E15: =Revenue!E35/Capex!E6 -> 1.8916002 | F15: =Revenue!F35/Capex!F6 -> 1.9848919 | G15: =F15+($K$15-$F$15)/5 -> 2.0879135 | H15: =G15+($K$15-$F$15)/5 -> 2.1909351 | I15: =H15+($K$15-$F$15)/5 -> 2.2939567 | J15: =I15+($K$15-$F$15)/5 -> 2.3969784 | K15: 2.5
A17: Amortization | C17: 89 | D17: 80 | E17: 72 | F17: 75 | G17: 68 | H17: 68 | I17: 68 | J17: 68 | K17: 68
A19: Other Intanzible assets | C19: ='Balance Sheet'!C12 -> 2462 | D19: ='Balance Sheet'!D12 -> 1920 | E19: ='Balance Sheet'!E12 -> 1887 | F19: ='Balance Sheet'!F12 -> 1756 | G19: =G20+G21 -> 1688 | H19: =H20+H21 -> 1620 | I19: =I20+I21 -> 1552 | J19: =J20+J21 -> 1484 | K19: =K20+K21 -> 1416
A20: Other Intanzible assets(with Indefnite life) | C20: 1561 | D20: 1212 | E20: 978 | F20: 948 | G20: =F20 -> 948 | H20: =G20 -> 948 | I20: =H20 -> 948 | J20: =I20 -> 948 | K20: =J20 -> 948
A21: Other Intanzible assets(with defnite life) | C21: =C19-C20 -> 901 | D21: =D19-D20 -> 708 | E21: =E19-E20 -> 909 | F21: =F19-F20 -> 808 | G21: =G28 -> 740 | H21: =H28 -> 672 | I21: =I28 -> 604 | J21: =J28 -> 536 | K21: =K28 -> 468
A23: Other Intanzible assets(with defnitie life)
A24: Opening Gross Block | C24: =902+786 -> 1688 | D24: =C26 -> 1635 | E24: =D26 -> 1501 | F24: =E26 -> 1791 | G24: =F26 -> 1738 | H24: =G26 -> 1738 | I24: =H26 -> 1738 | J24: =I26 -> 1738 | K24: =J26 -> 1738
A25: Add:Purchases | C25: =C24-C26 -> 53 | D25: =D24-D26 -> 134 | E25: =E24-E26 -> -290 | F25: =F24-F26 -> 53 | G25: 0 | H25: 0 | I25: 0 | J25: 0 | K25: 0
A26: Closing Gross Block | C26: =C28+C27 -> 1635 | D26: =D28+D27 -> 1501 | E26: =E28+E27 -> 1791 | F26: =F28+F27 -> 1738 | G26: =G24+G25 -> 1738 | H26: =H24+H25 -> 1738 | I26: =I24+I25 -> 1738 | J26: =J24+J25 -> 1738 | K26: =K24+K25 -> 1738
A27: Less: accumulated amortization | C27: 734 | D27: 793 | E27: 882 | F27: 930 | G27: =F27+G17 -> 998 | H27: =G27+H17 -> 1066 | I27: =H27+I17 -> 1134 | J27: =I27+J17 -> 1202 | K27: =J27+K17 -> 1270
A28: Net Block | C28: =C21 -> 901 | D28: =D21 -> 708 | E28: =E21 -> 909 | F28: =F21 -> 808 | G28: =G26-G27 -> 740 | H28: =H26-H27 -> 672 | I28: =I26-I27 -> 604 | J28: =J26-J27 -> 536 | K28: =K26-K27 -> 468
